<?xml version="1.0" ?>
<!-- =================================================================================== -->
<!-- |    This document was autogenerated by xacro from /home/sahasra/eva_ws/src/eva_h1_description/urdf/eva_h1.urdf.xacro | -->
<!-- |    EDITING THIS FILE BY HAND IS NOT RECOMMENDED                                 | -->
<!-- =================================================================================== -->
<robot name="eva_h1">
  <link name="base_link">
    <visual>
      <geometry>
        <box size="0.5 0.5 0.3"/>
      </geometry>
    </visual>
    <collision>
      <geometry>
        <box size="0.5 0.5 0.3"/>
      </geometry>
    </collision>
    <inertial>
      <mass value="5.0"/>
      <inertia ixx="0.1" ixy="0" ixz="0" iyy="0.1" iyz="0" izz="0.1"/>
    </inertial>
  </link>
  <link name="torso_link">
    <visual>
      <geometry>
        <box size="0.3 0.3 0.4"/>
      </geometry>
    </visual>
    <collision>
      <geometry>
        <box size="0.3 0.3 0.4"/>
      </geometry>
    </collision>
    <inertial>
      <origin rpy="0 0 0" xyz="0 0 0"/>
      <mass value="3.0"/>
      <inertia ixx="0.05" ixy="0" ixz="0" iyy="0.05" iyz="0" izz="0.05"/>
    </inertial>
  </link>
  <joint name="torso_joint" type="fixed">
    <parent link="base_link"/>
    <child link="torso_link"/>
    <origin xyz="0 0 0.35"/>
  </joint>
  <link name="neck_link">
    <visual>
      <geometry>
        <cylinder length="0.08" radius="0.04"/>
      </geometry>
    </visual>
    <collision>
      <geometry>
        <cylinder length="0.08" radius="0.04"/>
      </geometry>
    </collision>
    <inertial>
      <origin rpy="0 0 0" xyz="0 0 0"/>
      <mass value="0.3"/>
      <inertia ixx="0.001" ixy="0" ixz="0" iyy="0.001" iyz="0" izz="0.001"/>
    </inertial>
  </link>
  <joint name="neck_joint" type="fixed">
    <parent link="torso_link"/>
    <child link="neck_link"/>
    <origin xyz="0 0 0.24"/>
  </joint>
  <link name="head_link">
    <visual>
      <geometry>
        <box size="0.22 0.18 0.18"/>
      </geometry>
    </visual>
    <collision>
      <geometry>
        <box size="0.22 0.18 0.18"/>
      </geometry>
    </collision>
    <inertial>
      <origin rpy="0 0 0" xyz="0 0 0"/>
      <mass value="1.0"/>
      <inertia ixx="0.01" ixy="0" ixz="0" iyy="0.01" iyz="0" izz="0.01"/>
    </inertial>
  </link>
  <joint name="head_joint" type="fixed">
    <parent link="neck_link"/>
    <child link="head_link"/>
    <origin xyz="0 0 0.13"/>
  </joint>
  <link name="shoulder_link">
    <visual>
      <geometry>
        <box size="0.4 0.08 0.08"/>
      </geometry>
    </visual>
    <collision>
      <geometry>
        <box size="0.4 0.08 0.08"/>
      </geometry>
    </collision>
    <inertial>
      <origin rpy="0 0 0" xyz="0 0 0"/>
      <mass value="1.0"/>
      <inertia ixx="0.01" ixy="0" ixz="0" iyy="0.01" iyz="0" izz="0.01"/>
    </inertial>
  </link>
  <joint name="shoulder_joint" type="fixed">
    <parent link="torso_link"/>
    <child link="shoulder_link"/>
    <origin xyz="0 0 0.12"/>
  </joint>
  <link name="left_upper_arm_link">
    <visual>
      <geometry>
        <cylinder length="0.25" radius="0.03"/>
      </geometry>
    </visual>
    <collision>
      <geometry>
        <cylinder length="0.25" radius="0.03"/>
      </geometry>
    </collision>
    <inertial>
      <origin rpy="0 0 0" xyz="0 0 0"/>
      <mass value="0.8"/>
      <inertia ixx="0.005" ixy="0" ixz="0" iyy="0.005" iyz="0" izz="0.005"/>
    </inertial>
  </link>
  <joint name="left_upper_arm_joint" type="fixed">
    <parent link="shoulder_link"/>
    <child link="left_upper_arm_link"/>
    <origin xyz="-0.23 0 -0.13"/>
  </joint>
  <link name="right_upper_arm_link">
    <visual>
      <geometry>
        <cylinder length="0.25" radius="0.03"/>
      </geometry>
    </visual>
    <collision>
      <geometry>
        <cylinder length="0.25" radius="0.03"/>
      </geometry>
    </collision>
    <inertial>
      <origin rpy="0 0 0" xyz="0 0 0"/>
      <mass value="0.8"/>
      <inertia ixx="0.005" ixy="0" ixz="0" iyy="0.005" iyz="0" izz="0.005"/>
    </inertial>
  </link>
  <joint name="right_upper_arm_joint" type="fixed">
    <parent link="shoulder_link"/>
    <child link="right_upper_arm_link"/>
    <origin xyz="0.23 0 -0.13"/>
  </joint>
  <link name="left_axle_link">
    <visual>
      <geometry>
        <box size="0.14 0.04 0.04"/>
      </geometry>
    </visual>
    <collision>
      <geometry>
        <box size="0.14 0.04 0.04"/>
      </geometry>
    </collision>
    <inertial>
      <origin rpy="0 0 0" xyz="0 0 0"/>
      <mass value="0.3"/>
      <inertia ixx="0.001" ixy="0" ixz="0" iyy="0.001" iyz="0" izz="0.001"/>
    </inertial>
  </link>
  <joint name="left_axle_joint" type="fixed">
    <parent link="base_link"/>
    <child link="left_axle_link"/>
    <origin xyz="0.28 0 -0.10"/>
  </joint>
  <link name="left_wheel_link">
    <visual>
      <geometry>
        <cylinder length="0.05" radius="0.1"/>
      </geometry>
    </visual>
    <collision>
      <geometry>
        <cylinder length="0.05" radius="0.1"/>
      </geometry>
    </collision>
    <inertial>
      <origin rpy="0 0 0" xyz="0 0 0"/>
      <mass value="1.0"/>
      <inertia ixx="0.01" ixy="0" ixz="0" iyy="0.01" iyz="0" izz="0.01"/>
    </inertial>
  </link>
  <joint name="left_wheel_joint" type="continuous">
    <parent link="left_axle_link"/>
    <child link="left_wheel_link"/>
    <origin rpy="0 1.5708 0" xyz="0.07 0 -0.05"/>
    <axis xyz="0 1 0"/>
  </joint>
  <link name="right_axle_link">
    <visual>
      <geometry>
        <box size="0.14 0.04 0.04"/>
      </geometry>
    </visual>
    <collision>
      <geometry>
        <box size="0.14 0.04 0.04"/>
      </geometry>
    </collision>
    <inertial>
      <origin rpy="0 0 0" xyz="0 0 0"/>
      <mass value="0.3"/>
      <inertia ixx="0.001" ixy="0" ixz="0" iyy="0.001" iyz="0" izz="0.001"/>
    </inertial>
  </link>
  <joint name="right_axle_joint" type="fixed">
    <parent link="base_link"/>
    <child link="right_axle_link"/>
    <origin xyz="-0.28 0 -0.10"/>
  </joint>
  <link name="right_wheel_link">
    <visual>
      <geometry>
        <cylinder length="0.05" radius="0.1"/>
      </geometry>
    </visual>
    <collision>
      <geometry>
        <cylinder length="0.05" radius="0.1"/>
      </geometry>
    </collision>
    <inertial>
      <origin rpy="0 0 0" xyz="0 0 0"/>
      <mass value="1.0"/>
      <inertia ixx="0.01" ixy="0" ixz="0" iyy="0.01" iyz="0" izz="0.01"/>
    </inertial>
  </link>
  <joint name="right_wheel_joint" type="continuous">
    <parent link="right_axle_link"/>
    <child link="right_wheel_link"/>
    <origin rpy="0 1.5708 0" xyz="-0.07 0 -0.05"/>
    <axis xyz="0 1 0"/>
  </joint>
  <ros2_control name="EvaH1System" type="system">
    <hardware>
      <plugin>gazebo_ros2_control/GazeboSystem</plugin>
    </hardware>
    <joint name="left_wheel_joint">
      <command_interface name="velocity"/>
      <state_interface name="position"/>
      <state_interface name="velocity"/>
    </joint>
    <joint name="right_wheel_joint">
      <command_interface name="velocity"/>
      <state_interface name="position"/>
      <state_interface name="velocity"/>
    </joint>
  </ros2_control>
  <gazebo>
    <plugin filename="libgazebo_ros2_control.so" name="gazebo_ros2_control">
      <parameters>/home/sahasra/eva_ws/install/eva_h1_description/share/eva_h1_description/config/controllers.yaml</parameters>
    </plugin>
  </gazebo>
  S

</robot>
